{"frames":[{"func":"predict(model, x) %>% as.numeric()","file":"","line_number":0,"end_line_number":0,"character_number":0,"end_character_number":0},{"func":"predict(model, x)","file":"","line_number":0,"end_line_number":0,"character_number":0,"end_character_number":0},{"func":"predict.keras.engine.training.Model(model, x)","file":"","line_number":0,"end_line_number":0,"character_number":0,"end_character_number":0},{"func":"do.call(object$predict, args)","file":"","line_number":0,"end_line_number":0,"character_number":0,"end_character_number":0},{"func":"(structure(function (x, batch_size = NULL, verbose = \"auto\", \n    steps = NULL, callbacks = NULL, max_queue_size = 10L, workers = 1L, \n    use_multiprocessing = FALSE) \n{ ...","file":"","line_number":0,"end_line_number":0,"character_number":0,"end_character_number":0},{"func":"error_handler","file":"/Users/cnguyen/.virtualenvs/r-tensorflow/lib/python3.10/site-packages/keras/src/utils/traceback_utils.py","line_number":"70","end_line_nubmer":"70","character_number":0.0},{"func":"tf__predict_function","file":"/var/folders/tr/c0z116851wj071hh7yqtt_1h0000gn/T/__autograph_generated_file_l986ohe.py","line_number":"15","end_line_nubmer":"15","character_number":0.0},{"func":"stop(structure(list(message = \"ValueError: in user code:\\n\\n<...truncated...>predict_step\\n        return self(x, training=False)\\n    File \\\"/Users/cnguyen/.virtualenvs/r-tensorflow/lib/python3.10/site-packages/keras/src/utils/traceback_utils.py\\\", line 70, in error_handler\\n        raise e.with_traceback(filtered_tb) from None\\n    File \\\"/Users/cnguyen/.virtualenvs/r-tensorflow/lib/python3.10/site-packages/keras/src/engine/input_spec.py\\\", line 235, in assert_input_compatibility\\n        raise ValueError(\\n\\n    ValueError: Exception encountered when calling layer 'sequential' (type Sequential).\\n    \\n    Input 0 of layer \\\"simple_rnn\\\" is incompatible with the layer: expected ndim=3, found ndim=2. Full shape received: (None, 128)\\n    \\n    Call arguments received by layer 'sequential' (type Sequential):\\n      • inputs=tf.Tensor(shape=(None,), dtype=string)\\n      • training=False\\n      • mask=None\\n\\n\\033[90mRun \\033]8;;rstudio:run:reticulate::py_last_error()\\a`reticulate::py_last_error()`\\033]8;;\\a for details.\\033[39m\", \n    call = py_call_impl(callable, call_args$unnamed, call_args$named)), class = c(\"python.builtin.ValueError\", \n\"python.builtin.Exception\", \"python.builtin.BaseException\", \"python.builtin.object\", \n\"error\", \"condition\"), py_object = <environment>))","file":"","line_number":0,"end_line_number":0,"character_number":0,"end_character_number":0}],"message":"Error in py_call_impl(callable, call_args$unnamed, call_args$named) : \n  ValueError: in user code:\n\n<...truncated...>predict_step\n        return self(x, training=False)\n    File \"/Users/cnguyen/.virtualenvs/r-tensorflow/lib/python3.10/site-packages/keras/src/utils/traceback_utils.py\", line 70, in error_handler\n        raise e.with_traceback(filtered_tb) from None\n    File \"/Users/cnguyen/.virtualenvs/r-tensorflow/lib/python3.10/site-packages/keras/src/engine/input_spec.py\", line 235, in assert_input_compatibility\n        raise ValueError(\n\n    ValueError: Exception encountered when calling layer 'sequential' (type Sequential).\n    \n    Input 0 of layer \"simple_rnn\" is incompatible with the layer: expected ndim=3, found ndim=2. Full shape received: (None, 128)\n    \n    Call arguments received by layer 'sequential' (type Sequential):\n      • inputs=tf.Tensor(shape=(None,), dtype=string)\n      • training=False\n      • mask=None\n\n\u001B[90mRun \u001B]8;;rstudio:run:reticulate::py_last_error()\u0007`reticulate::py_last_error()`\u001B]8;;\u0007 for details.\u001B[39m\n"}